Workbook

Sheet 概要
A1: 原マシナリー 宣伝ミュージックビデオ 企画書
A2: 曲の解析とホームページ情報から作成した、完成イメージの設計図です。青字のセルは変更できる入力値です。
A3: コンセプト | B3: 「削る、受け継ぐ、切り拓く」。工具の軌跡（光の線）と削り出した面の金属光沢を共通のモチーフにして、1948年からの歴史・精度・素材・人・未来を一本の線でつなぐ。
A4: 映像のトーン | B4: 鉄の濃紺とスチールグレーを基調に、切削面の光沢を思わせるアンバーを差し色にする。前半は重厚、サビで力強く、Cメロで温かく、ラストサビで最大の盛り上がりにする。
A5: 曲の長さ（秒） | B5: 275.8
A6: テンポ（BPM） | B6: 143.6
A7: 1小節の長さ（秒） | B7: =60/B6*4
A8: 曲の小節数（推定） | B8: =ROUND(B5/B7,0)
A9: 構成 | B9: イントロ → Aメロ1・2 → Bメロ1 → サビ1 → 間奏 → Aメロ3 → Bメロ2 → サビ2 → Cメロ → ラストサビ → アウトロ（全12パート）
A10: パート数 | B10: =COUNTA('構成・絵コンテ'!B5:B16)
A11: 使うスタイルの種類 | B11: =COUNTA('スタイル組み合わせ'!B5:B27)
A12: 制作の土台 | B12: Remotion（React で映像を組み立て、曲の拍に合わせて動かす）＋ Three.js（3D）＋ FFmpeg（色補正・書き出し）
A13: 拍合わせの方法 | B13: Python の librosa で検出した拍の位置（このファイルの「曲の解析」シート）を Remotion に読み込み、カットや文字を拍ぴったりに配置する。
A14: 映像の方向性（改訂） | B14: 参考動画（Google Flow で作成）と同じ手描きアニメ調で、3世代の技術者が技術を受け継ぐ物語にする。人物や工場の場面は Google Flow で生成し（「アニメ版カット表」）、Claude Code が曲の拍に合わせた編集・歌詞テロップ・年号カウンター・工具の軌跡の線・ロゴ・エンドカードを重ねて仕上げる。「構成・絵コンテ」の CG 表現は、この重ねる演出として使う。
A15: 表現の禁止事項 | B15: 火花の表現は使わない（CG・写真・効果音とも）。切削の表現は、工具の軌跡の線と金属の光沢で行う。
A16: 重要な注意 | B16: パートの開始・終了時刻は、曲の自動解析から出した推定値です。歌詞の文字起こしモデルがこの作業環境から使えなかったため、歌詞と時刻の対応は実際に聴いて確認・修正してください（「構成・絵コンテ」の青字を直すと、すべての時刻と長さが自動で再計算されます）。
A17: 曲について | B17: 音源のメタデータに Suno（AI作曲サービス）で作成されたと記録されています。宣伝に使う場合は、作成時のプランの商用利用条件を確認してください。

Sheet 登場人物と画風
A1: 登場人物と画風（Google Flow 用）
A2: 全カットで見た目を揃えるため、先に Flow で人物と場所の画像を作り、各カットの Ingredients（参照画像、最大3つ）として使います。
A4: 区分 | B4: 名前 | C4: 見た目（日本語） | D4: プロンプト用の英語（コピーして使う）
A5: 画風 | B5: 全カット共通 | C5: 参考動画と同じ、手描きアニメ映画風。柔らかい手描き背景、窓からの自然光、落ち着いた色、薄いフィルムの粒子。画面内に文字・ロゴ・火花を入れない（文字とロゴは Claude Code が後から入れる）。 | D5: Japanese hand-drawn anime film style, soft painterly backgrounds, warm natural light, muted colors, gentle film grain, cinematic 16:9. No on-screen text, no logos, no sparks.
A6: 人物 | B6: 初代の職人（1948年） | C6: 20代の男性。短い黒髪、紺の作業着。創業期の小さな町工場で働く。セピア調の場面だけに登場。 | D6: a Japanese man in his twenties with short black hair, wearing a navy work jacket, in a small 1940s workshop
A7: 人物 | B7: ベテラン職人（現在） | C7: 70代の男性。白髪を後ろへ流し、紺の作業着。手描きの図面と鉛筆。参考動画の1人目と同じ見た目。 | D7: an elderly Japanese craftsman in his seventies with swept-back grey hair, wearing a navy work jacket
A8: 人物 | B8: 中堅の技術者 | C8: 40代の男性。短い黒髪、袖をまくった白いシャツ。製図台と工作機械の両方に立つ。参考動画の2人目。 | D8: a Japanese man in his forties with short dark hair, white shirt with rolled-up sleeves
A9: 人物 | B9: 若手の設計者 | C9: 20代の女性。茶色のボブ、丸い眼鏡、白いシャツ。CAD で設計する。参考動画の3人目・最後のカット。 | D9: a young Japanese woman in her twenties with a brown bob haircut and round glasses, wearing a white shirt
A10: 人物 | B10: 若手のオペレーター | C10: 20代の男性。短髪、紺の作業服、保護メガネ。門型5面加工機を操作する。 | D10: a young Japanese man in his twenties with short hair, navy work uniform and safety glasses
A11: 場所 | B11: 創業期の町工場（1948年） | C11: 木の梁、窓からの斜光、古い工作機械。セピア調。 | D11: a small 1940s Japanese machine workshop with wooden beams and old machines, sepia tones
A12: 場所 | B12: 現在の工場 | C12: 天井の高い明るい工場。大型の門型5面加工機。床は清潔。 | D12: a bright, high-ceilinged modern Japanese factory with a large gantry-type five-face machining center, clean floor
A13: 場所 | B13: 設計室 | C13: 窓際の机、CAD のモニター、壁に貼られた図面。 | D13: a calm design office by the window with CAD monitors and drawings pinned on the wall
A14: 場所 | B14: 岡崎の街 | C14: 矢作川の流れる街並み。丘の上から見下ろす。 | D14: the city of Okazaki in Aichi seen from a hill, with the Yahagi River flowing through it
A16: 注意
A17: ・人物は実在の社員を写したものではありません。実在の社員に似せる場合は、本人の同意を得た写真を Ingredients に使ってください。
A18: ・機械加工のカットは、AI が火花を描き足すことがあります。「火花の注意」列に印のあるカットは、生成後に必ず確認してください。
A19: ・AI 生成の地図や看板に出る文字は崩れやすいため、プロンプトでは文字なしにしています。地名や歌詞は Claude Code の編集で正確に入れます。

Sheet アニメ版カット表
A1: アニメ版カット表（Google Flow 生成用）
A2: 「プロンプト（コピー用）」をそのまま Flow に貼り付けて使えます。開始・長さは「構成・絵コンテ」の時刻から自動計算します。状態（黄色）を更新してください。
A4: No | B4: パート | C4: カット | D4: 開始（秒） | E4: 使う長さ（秒） | F4: Flow で生成する長さ（秒） | G4: 歌詞の目安 | H4: 場面 | I4: 登場人物 | J4: Flow の作り方 | K4: プロンプト（コピー用） | L4: Claude Code が編集で加えるもの | M4: 火花の注意 | N4: 状態
A5: 1 | B5: ='構成・絵コンテ'!B5 | C5: 地球から日本へ | D5: ='構成・絵コンテ'!C5 | E5: ='構成・絵コンテ'!E5/COUNTIF($B$5:$B$45,B5) | F5: ― | G5: （演奏） | H5: 宇宙の地球から日本列島へ、ゆっくり寄っていく。 | I5: ― | J5: 参考動画を流用 | K5: Slow push-in from space toward Earth, approaching the Japanese archipelago, soft clouds drifting. Japanese hand-drawn anime film style, soft painterly backgrounds, warm natural light, muted colors, gentle film grain, cinematic 16:9. No on-screen text, no logos, no sparks. | L5: 工具の軌跡の線で「1948」を描く | N5: 作成済み
A6: 2 | B6: ='構成・絵コンテ'!B5 | C6: 岡崎の朝 | D6: =IF(B6=B5,D5+E5,'構成・絵コンテ'!C5) | E6: ='構成・絵コンテ'!E5/COUNTIF($B$5:$B$45,B6) | F6: ― | G6: （演奏） | H6: 朝もやの岡崎の街と川。工場の屋根に朝日が当たる。 | I6: ― | J6: 参考動画を流用＋文字なしで再生成 | K6: Aerial descent over the city of Okazaki at dawn, morning mist over the Yahagi River, sunlight touching factory rooftops. Japanese hand-drawn anime film style, soft painterly backgrounds, warm natural light, muted colors, gentle film grain, cinematic 16:9. No on-screen text, no logos, no sparks. | L6: 地名「岡崎」のテロップ | N6: 作成済み
A7: 3 | B7: ='構成・絵コンテ'!B6 | C7: 1948年の町工場 | D7: =IF(B7=B6,D6+E6,'構成・絵コンテ'!C6) | E7: ='構成・絵コンテ'!E6/COUNTIF($B$5:$B$45,B7) | F7: =IF(E7>8,8,IF(E7>6,8,IF(E7>4,6,4))) | G7: 1948年 ここから始まった | H7: 創業期の小さな町工場で、若い職人が古い機械を手入れしている。 | I7: 初代の職人 | J7: Ingredients（初代の職人＋創業期の町工場） | K7: Medium shot. A young craftsman carefully wipes and adjusts an old machine in a small workshop, dust in the slanted window light. Japanese hand-drawn anime film style, soft painterly backgrounds, warm natural light, muted colors, gentle film grain, cinematic 16:9. No on-screen text, no logos, no sparks. | L7: 年号カウンター 1948、セピア→カラーの色補正 | N7: 未生成
A8: 4 | B8: ='構成・絵コンテ'!B6 | C8: 受け継がれる場所 | D8: =IF(B8=B7,D7+E7,'構成・絵コンテ'!C6) | E8: ='構成・絵コンテ'!E6/COUNTIF($B$5:$B$45,B8) | F8: =IF(E8>8,8,IF(E8>6,8,IF(E8>4,6,4))) | G8: 受け継いだ技術 積み重ねた想い／時代が変わっても | H8: 同じ構図で、現在のベテラン職人が同じ場所に立ち、古い写真を手に取る。 | I8: ベテラン職人 | J8: Frames to video（前カットの最終コマを開始フレームに） | K8: Same composition as the previous shot, now in the present day. An elderly craftsman stands in the same spot and gently picks up an old photograph, smiling softly. Japanese hand-drawn anime film style, soft painterly backgrounds, warm natural light, muted colors, gentle film grain, cinematic 16:9. No on-screen text, no logos, no sparks. | L8: 年号カウンター 1948→2026 | N8: 未生成
A9: 5 | B9: ='構成・絵コンテ'!B6 | C9: 今の工場へ | D9: =IF(B9=B8,D8+E8,'構成・絵コンテ'!C6) | E9: ='構成・絵コンテ'!E6/COUNTIF($B$5:$B$45,B9) | F9: =IF(E9>8,8,IF(E9>6,8,IF(E9>4,6,4))) | G9: 変わらないものがある／ものづくりへの 情熱 | H9: カメラが後ろへ引くと、明るく広い現在の工場が広がる。 | I9: ベテラン職人 | J9: Ingredients（ベテラン職人＋現在の工場） | K9: Slow dolly back revealing a bright, spacious modern factory around the elderly craftsman; colleagues working in the background. Japanese hand-drawn anime film style, soft painterly backgrounds, warm natural light, muted colors, gentle film grain, cinematic 16:9. No on-screen text, no logos, no sparks. | L9: 歌詞テロップ「情熱」を大きく | N9: 未生成
A10: 6 | B10: ='構成・絵コンテ'!B7 | C10: 大物を削る | D10: =IF(B10=B9,D9+E9,'構成・絵コンテ'!C7) | E10: ='構成・絵コンテ'!E7/COUNTIF($B$5:$B$45,B10) | F10: =IF(E10>8,8,IF(E10>6,8,IF(E10>4,6,4))) | G10: 鉄を削り 形を生み出す／大きな素材に 挑み続ける | H10: 門型5面加工機が大きな鋼材を静かに削る。削った面がなめらかに光る。 | I10: ― | J10: Ingredients（現在の工場） | K10: Low-angle wide shot. A large gantry-type machining center smoothly and quietly mills a huge steel block; the freshly machined surface gleams like a mirror. Clean, calm cutting. Japanese hand-drawn anime film style, soft painterly backgrounds, warm natural light, muted colors, gentle film grain, cinematic 16:9. No on-screen text, no logos, no sparks. | L10: 寸法線 5200×2600mm、工具の軌跡の線 | M10: 火花が出やすい。生成後に必ず確認 | N10: 未生成
A11: 7 | B11: ='構成・絵コンテ'!B7 | C11: 一ミクロンを測る | D11: =IF(B11=B10,D10+E10,'構成・絵コンテ'!C7) | E11: ='構成・絵コンテ'!E7/COUNTIF($B$5:$B$45,B11) | F11: =IF(E11>8,8,IF(E11>6,8,IF(E11>4,6,4))) | G11: 一ミリ 一ミクロン／その先にある精度を追い | H11: 若手オペレーターがマイクロメーターで部品を測る。手元と真剣な目のアップ。 | I11: 若手のオペレーター | J11: Ingredients（若手のオペレーター） | K11: Close-up. A young operator measures a polished metal part with a micrometer, focused eyes, then a macro shot of his fingertips adjusting the dial. Japanese hand-drawn anime film style, soft painterly backgrounds, warm natural light, muted colors, gentle film grain, cinematic 16:9. No on-screen text, no logos, no sparks. | L11: 目盛りが 1mm→1μm に拡大するグラフィック | N11: 未生成
A12: 8 | B12: ='構成・絵コンテ'!B7 | C12: 人から人へ | D12: =IF(B12=B11,D11+E11,'構成・絵コンテ'!C7) | E12: ='構成・絵コンテ'!E7/COUNTIF($B$5:$B$45,B12) | F12: ― | G12: 技術は 人から人へ／想いは 未来へ | H12: 職人が鉛筆で図面を引く→製図台→CAD→図面を手渡す（参考動画の場面）。 | I12: ベテラン職人・中堅の技術者・若手の設計者 | J12: 参考動画を流用 | K12: （参考動画をそのまま使用） | L12: 拍に合わせてカット割り、歌詞テロップ | N12: 作成済み
A13: 9 | B13: ='構成・絵コンテ'!B8 | C13: 守ると変える | D13: =IF(B13=B12,D12+E12,'構成・絵コンテ'!C8) | E13: ='構成・絵コンテ'!E8/COUNTIF($B$5:$B$45,B13) | F13: =IF(E13>8,8,IF(E13>6,8,IF(E13>4,6,4))) | G13: 守るべき技術は 守り抜く／変えるべきものは 変えていく | H13: ベテランが古い手描き図面を広げ、若手設計者がタブレットの CAD と見比べてうなずき合う。 | I13: ベテラン職人・若手の設計者 | J13: Ingredients（2人の人物） | K13: Two-shot at a workbench. The elderly craftsman unrolls an old hand-drawn blueprint; the young designer holds a tablet showing the same part in CAD. They compare and nod to each other. Japanese hand-drawn anime film style, soft painterly backgrounds, warm natural light, muted colors, gentle film grain, cinematic 16:9. No on-screen text, no logos, no sparks. | N13: 未生成
A14: 10 | B14: ='構成・絵コンテ'!B8 | C14: 夜明けのシャッター | D14: =IF(B14=B13,D13+E13,'構成・絵コンテ'!C8) | E14: ='構成・絵コンテ'!E8/COUNTIF($B$5:$B$45,B14) | F14: =IF(E14>8,8,IF(E14>6,8,IF(E14>4,6,4))) | G14: 昨日を超えて／今日を超えて／まだ見ぬ未来へ | H14: 夜明けの工場。大きなシャッターが上がり、朝日が一気に差し込む。 | I14: ― | J14: Ingredients（現在の工場） | K14: Inside the factory at dawn, the large shutter door rises and golden morning light floods in across the floor, camera slowly pushing forward. Japanese hand-drawn anime film style, soft painterly backgrounds, warm natural light, muted colors, gentle film grain, cinematic 16:9. No on-screen text, no logos, no sparks. | L14: サビへ向けて光の流れが加速 | N14: 未生成
A15: 11 | B15: ='構成・絵コンテ'!B9 | C15: 技術力 | D15: =IF(B15=B14,D14+E14,'構成・絵コンテ'!C9) | E15: ='構成・絵コンテ'!E9/COUNTIF($B$5:$B$45,B15) | F15: =IF(E15>8,8,IF(E15>6,8,IF(E15>4,6,4))) | G15: 技術力 | H15: オペレーターが操作盤に触れる。真剣な横顔。 | I15: 若手のオペレーター | J15: Ingredients | K15: Close-up profile of a young operator pressing buttons on a machine control panel, determined expression, rim light. Japanese hand-drawn anime film style, soft painterly backgrounds, warm natural light, muted colors, gentle film grain, cinematic 16:9. No on-screen text, no logos, no sparks. | L15: 「技術力」を画面いっぱいに（1拍） | N15: 未生成
A16: 12 | B16: ='構成・絵コンテ'!B9 | C16: 設計力 | D16: =IF(B16=B15,D15+E15,'構成・絵コンテ'!C9) | E16: ='構成・絵コンテ'!E9/COUNTIF($B$5:$B$45,B16) | F16: =IF(E16>8,8,IF(E16>6,8,IF(E16>4,6,4))) | G16: 設計力 | H16: 設計者の CAD 画面で、線が立体に組み上がっていく。 | I16: 若手の設計者 | J16: Ingredients | K16: Over-the-shoulder shot of a young designer working in CAD; lines on the monitor assemble into a 3D machine part. Japanese hand-drawn anime film style, soft painterly backgrounds, warm natural light, muted colors, gentle film grain, cinematic 16:9. No on-screen text, no logos, no sparks. | L16: 「設計力」（1拍） | N16: 未生成
A17: 13 | B17: ='構成・絵コンテ'!B9 | C17: 設備力 | D17: =IF(B17=B16,D16+E16,'構成・絵コンテ'!C9) | E17: ='構成・絵コンテ'!E9/COUNTIF($B$5:$B$45,B17) | F17: =IF(E17>8,8,IF(E17>6,8,IF(E17>4,6,4))) | G17: 設備力 | H17: 門型5面加工機の全景を、下から見上げる迫力のカット。 | I17: ― | J17: Ingredients（現在の工場） | K17: Dramatic low-angle shot slowly tilting up the full height of a huge gantry-type machining center in a bright factory. Japanese hand-drawn anime film style, soft painterly backgrounds, warm natural light, muted colors, gentle film grain, cinematic 16:9. No on-screen text, no logos, no sparks. | L17: 「設備力」（1拍） | N17: 未生成
A18: 14 | B18: ='構成・絵コンテ'!B9 | C18: 人間力 | D18: =IF(B18=B17,D17+E17,'構成・絵コンテ'!C9) | E18: ='構成・絵コンテ'!E9/COUNTIF($B$5:$B$45,B18) | F18: =IF(E18>8,8,IF(E18>6,8,IF(E18>4,6,4))) | G18: 人間力／すべての力を ひとつにして／まだない価値を 創り出せ | H18: 仲間が図面を囲み、笑顔で話し合う。 | I18: 全員 | J18: Ingredients（人物2〜3人） | K18: A small team gathered around a large blueprint on a table, pointing and laughing together, warm window light. Japanese hand-drawn anime film style, soft painterly backgrounds, warm natural light, muted colors, gentle film grain, cinematic 16:9. No on-screen text, no logos, no sparks. | L18: 「人間力」（1拍） | N18: 未生成
A19: 15 | B19: ='構成・絵コンテ'!B9 | C19: 未来を切り拓け | D19: =IF(B19=B18,D18+E18,'構成・絵コンテ'!C9) | E19: ='構成・絵コンテ'!E9/COUNTIF($B$5:$B$45,B19) | F19: =IF(E19>8,8,IF(E19>6,8,IF(E19>4,6,4))) | G19: この手で／この技術で／未来を 切り拓け／原マシナリー | H19: 工場の大扉が開き、光の中へ社員たちが歩み出る後ろ姿。 | I19: 全員 | J19: Ingredients | K19: Back view of employees walking together toward a wide-open factory door filled with bright light, camera following low. Japanese hand-drawn anime film style, soft painterly backgrounds, warm natural light, muted colors, gentle film grain, cinematic 16:9. No on-screen text, no logos, no sparks. | L19: ロゴを中央に（光沢が横切る） | N19: 未生成
A20: 16 | B20: ='構成・絵コンテ'!B10 | C20: 夕日の機械 | D20: =IF(B20=B19,D19+E19,'構成・絵コンテ'!C10) | E20: ='構成・絵コンテ'!E10/COUNTIF($B$5:$B$45,B20) | F20: =IF(E20>8,8,IF(E20>6,8,IF(E20>4,6,4))) | G20: （演奏） | H20: 静かな工場。機械の金属面に夕日が反射する。 | I20: ― | J20: Ingredients（現在の工場） | K20: Quiet empty factory at sunset; warm light reflects off the polished metal surfaces of the machines, slow lateral pan. Japanese hand-drawn anime film style, soft painterly backgrounds, warm natural light, muted colors, gentle film grain, cinematic 16:9. No on-screen text, no logos, no sparks. | L20: 音の波形のライン、グリッチ転換 | N20: 未生成
A21: 17 | B21: ='構成・絵コンテ'!B11 | C21: 4つの素材 | D21: =IF(B21=B20,D20+E20,'構成・絵コンテ'!C11) | E21: ='構成・絵コンテ'!E11/COUNTIF($B$5:$B$45,B21) | F21: =IF(E21>8,8,IF(E21>6,8,IF(E21>4,6,4))) | G21: 難しい素材も 不可能じゃない／シリコン サファイア ガラス 石英 | H21: 作業台に、シリコンの塊・サファイア・ガラス・石英が並び、窓の光で輝く。 | I21: ― | J21: Text to video | K21: Macro tracking shot along a workbench where a silicon ingot, a clear sapphire block, a glass plate and a milky quartz piece are lined up, glowing in window light. Japanese hand-drawn anime film style, soft painterly backgrounds, warm natural light, muted colors, gentle film grain, cinematic 16:9. No on-screen text, no logos, no sparks. | L21: 素材名を1拍ずつテロップ | N21: 未生成
A22: 18 | B22: ='構成・絵コンテ'!B11 | C22: 組み上げる | D22: =IF(B22=B21,D21+E21,'構成・絵コンテ'!C11) | E22: ='構成・絵コンテ'!E11/COUNTIF($B$5:$B$45,B22) | F22: =IF(E22>8,8,IF(E22>6,8,IF(E22>4,6,4))) | G22: 削る 磨く 組み上げる／一つひとつに 技術が宿る | H22: 技術者たちが専用機を組み立てる。ボルトを締める手元のアップ。 | I22: 中堅の技術者・若手のオペレーター | J22: Ingredients | K22: Close-up of hands assembling a special-purpose machine, tightening bolts with a torque wrench, then a medium shot of two engineers working together. Japanese hand-drawn anime film style, soft painterly backgrounds, warm natural light, muted colors, gentle film grain, cinematic 16:9. No on-screen text, no logos, no sparks. | L22: 「削る／磨く／組み上げる」の3語 | N22: 未生成
A23: 19 | B23: ='構成・絵コンテ'!B11 | C23: 一貫して応える | D23: =IF(B23=B22,D22+E22,'構成・絵コンテ'!C11) | E23: ='構成・絵コンテ'!E11/COUNTIF($B$5:$B$45,B23) | F23: =IF(E23>8,8,IF(E23>6,8,IF(E23>4,6,4))) | G23: 設計から 加工まで／一貫して 応えていく／求められるものの／その先へ | H23: 完成した専用機の前で、設計者とオペレーターがうなずき合う。 | I23: 若手の設計者・若手のオペレーター | J23: Ingredients | K23: The young designer and the young operator stand in front of a finished machine, exchange a nod and a small smile. Japanese hand-drawn anime film style, soft painterly backgrounds, warm natural light, muted colors, gentle film grain, cinematic 16:9. No on-screen text, no logos, no sparks. | N23: 未生成
A24: 20 | B24: ='構成・絵コンテ'!B12 | C24: 品質を測る | D24: =IF(B24=B23,D23+E23,'構成・絵コンテ'!C12) | E24: ='構成・絵コンテ'!E12/COUNTIF($B$5:$B$45,B24) | F24: =IF(E24>8,8,IF(E24>6,8,IF(E24>4,6,4))) | G24: 品質を追い／コストに挑み／納期を守る | H24: 検査室で三次元測定機が部品を測り、若手が記録する。 | I24: 若手の設計者 | J24: Ingredients | K24: A clean inspection room; a coordinate measuring machine probe touches a metal part while a young staff member records the results on a clipboard. Japanese hand-drawn anime film style, soft painterly backgrounds, warm natural light, muted colors, gentle film grain, cinematic 16:9. No on-screen text, no logos, no sparks. | L24: 品質・コスト・納期のチェック表示 | N24: 未生成
A25: 21 | B25: ='構成・絵コンテ'!B12 | C25: 信頼を届ける | D25: =IF(B25=B24,D24+E24,'構成・絵コンテ'!C12) | E25: ='構成・絵コンテ'!E12/COUNTIF($B$5:$B$45,B25) | F25: =IF(E25>8,8,IF(E25>6,8,IF(E25>4,6,4))) | G25: 信頼は／一つひとつの仕事から／積み上げていく | H25: 出荷。製品を丁寧にトラックへ積み、お辞儀して見送る。 | I25: 中堅の技術者 | J25: Ingredients | K25: A carefully wrapped machine part is loaded onto a truck; the engineer bows politely as the truck departs in the afternoon light. Japanese hand-drawn anime film style, soft painterly backgrounds, warm natural light, muted colors, gentle film grain, cinematic 16:9. No on-screen text, no logos, no sparks. | N25: 未生成
A26: 22 | B26: ='構成・絵コンテ'!B13 | C26: 手を取って教える | D26: =IF(B26=B25,D25+E25,'構成・絵コンテ'!C13) | E26: ='構成・絵コンテ'!E13/COUNTIF($B$5:$B$45,B26) | F26: =IF(E26>8,8,IF(E26>6,8,IF(E26>4,6,4))) | G26: 技術力 設計力 | H26: ベテランが若手の手に手を添えて、工具の当て方を教える。 | I26: ベテラン職人・若手のオペレーター | J26: Ingredients | K26: Close-up: an elderly craftsman places his hand over a young operator's hand, guiding how to hold a precision tool. Japanese hand-drawn anime film style, soft painterly backgrounds, warm natural light, muted colors, gentle film grain, cinematic 16:9. No on-screen text, no logos, no sparks. | L26: 「技術力」「設計力」 | N26: 未生成
A27: 23 | B27: ='構成・絵コンテ'!B13 | C27: 新しい設備 | D27: =IF(B27=B26,D26+E26,'構成・絵コンテ'!C13) | E27: ='構成・絵コンテ'!E13/COUNTIF($B$5:$B$45,B27) | F27: =IF(E27>8,8,IF(E27>6,8,IF(E27>4,6,4))) | G27: 設備力 人間力／受け継いだ力を 進化させ | H27: 新しい機械が稼働を始め、社員が拍手する。 | I27: 全員 | J27: Ingredients | K27: A new machine powers on with its indicator lights; employees around it applaud and smile. Japanese hand-drawn anime film style, soft painterly backgrounds, warm natural light, muted colors, gentle film grain, cinematic 16:9. No on-screen text, no logos, no sparks. | L27: 「設備力」「人間力」 | N27: 未生成
A28: 24 | B28: ='構成・絵コンテ'!B13 | C28: 次の時代へ | D28: =IF(B28=B27,D27+E27,'構成・絵コンテ'!C13) | E28: ='構成・絵コンテ'!E13/COUNTIF($B$5:$B$45,B28) | F28: =IF(E28>8,8,IF(E28>6,8,IF(E28>4,6,4))) | G28: 次の時代を 創り出せ | H28: 設計者がホワイトボードで説明し、仲間がうなずく。 | I28: 若手の設計者・中堅の技術者 | J28: Ingredients | K28: The young designer explains a sketch on a whiteboard to colleagues who nod with interest. Japanese hand-drawn anime film style, soft painterly backgrounds, warm natural light, muted colors, gentle film grain, cinematic 16:9. No on-screen text, no logos, no sparks. | N28: 未生成
A29: 25 | B29: ='構成・絵コンテ'!B13 | C29: この街から | D29: =IF(B29=B28,D28+E28,'構成・絵コンテ'!C13) | E29: ='構成・絵コンテ'!E13/COUNTIF($B$5:$B$45,B29) | F29: =IF(E29>8,8,IF(E29>6,8,IF(E29>4,6,4))) | G29: この街から | H29: 夕方、丘の上から岡崎の街と工場を見下ろす。 | I29: ― | J29: Ingredients（岡崎の街） | K29: Wide shot at golden hour overlooking the city of Okazaki from a hill, a factory roof in the foreground. Japanese hand-drawn anime film style, soft painterly backgrounds, warm natural light, muted colors, gentle film grain, cinematic 16:9. No on-screen text, no logos, no sparks. | L29: 地名「岡崎」 | N29: 未生成
A30: 26 | B30: ='構成・絵コンテ'!B13 | C30: 世界へ | D30: =IF(B30=B29,D29+E29,'構成・絵コンテ'!C13) | E30: ='構成・絵コンテ'!E13/COUNTIF($B$5:$B$45,B30) | F30: ― | G30: 世界へ／未来を 動かせ／原マシナリー | H30: カメラが空へ上がり、地球までズームアウトする。 | I30: ― | J30: 参考動画を逆再生して流用 | K30: （冒頭の参考動画を逆再生で使用） | L30: ロゴ | N30: 作成済み
A31: 27 | B31: ='構成・絵コンテ'!B14 | C31: 人がいる | D31: =IF(B31=B30,D30+E30,'構成・絵コンテ'!C14) | E31: ='構成・絵コンテ'!E14/COUNTIF($B$5:$B$45,B31) | F31: =IF(E31>8,8,IF(E31>6,8,IF(E31>4,6,4))) | G31: 変化を恐れない／挑戦を止めない／人がいる | H31: 朝礼。社員が並び、前を向く。 | I31: 全員 | J31: Ingredients | K31: Morning assembly in the factory: employees stand in a row, listening and looking ahead, soft morning light. Japanese hand-drawn anime film style, soft painterly backgrounds, warm natural light, muted colors, gentle film grain, cinematic 16:9. No on-screen text, no logos, no sparks. | N31: 未生成
A32: 28 | B32: ='構成・絵コンテ'!B14 | C32: 仲間がいる | D32: =IF(B32=B31,D31+E31,'構成・絵コンテ'!C14) | E32: ='構成・絵コンテ'!E14/COUNTIF($B$5:$B$45,B32) | F32: =IF(E32>8,8,IF(E32>6,8,IF(E32>4,6,4))) | G32: 技術がある／仲間がいる | H32: 昼休み、社員が笑いながら弁当を食べる。 | I32: 全員 | J32: Ingredients | K32: Lunch break: employees laughing together while eating bento boxes at a long table, relaxed and warm. Japanese hand-drawn anime film style, soft painterly backgrounds, warm natural light, muted colors, gentle film grain, cinematic 16:9. No on-screen text, no logos, no sparks. | N32: 未生成
A33: 29 | B33: ='構成・絵コンテ'!B14 | C33: だから できる | D33: =IF(B33=B32,D32+E32,'構成・絵コンテ'!C14) | E33: ='構成・絵コンテ'!E14/COUNTIF($B$5:$B$45,B33) | F33: ― | G33: だから できる | H33: 窓辺で若手設計者が微笑む（参考動画の最後のカット）。 | I33: 若手の設計者 | J33: 参考動画を流用 | K33: （参考動画の最後のカットを使用） | L33: 1拍の静止 → グリッチでラストサビへ | N33: 作成済み
A34: 30 | B34: ='構成・絵コンテ'!B14 | C34: 一つの会社から | D34: =IF(B34=B33,D33+E33,'構成・絵コンテ'!C14) | E34: ='構成・絵コンテ'!E14/COUNTIF($B$5:$B$45,B34) | F34: =IF(E34>8,8,IF(E34>6,8,IF(E34>4,6,4))) | G34: 一つの会社から／一つの技術から／世界の未来へ | H34: 夕暮れ、工場の窓に明かりがともる外観。 | I34: ― | J34: Ingredients（現在の工場） | K34: Exterior of the factory at dusk, windows lighting up one by one, sky turning from orange to blue. Japanese hand-drawn anime film style, soft painterly backgrounds, warm natural light, muted colors, gentle film grain, cinematic 16:9. No on-screen text, no logos, no sparks. | N34: 未生成
A35: 31 | B35: ='構成・絵コンテ'!B15 | C35: 1948年の手 | D35: =IF(B35=B34,D34+E34,'構成・絵コンテ'!C15) | E35: ='構成・絵コンテ'!E15/COUNTIF($B$5:$B$45,B35) | F35: =IF(E35>8,8,IF(E35>6,8,IF(E35>4,6,4))) | G35: 技術力 設計力 | H35: セピア調。初代の職人が古い機械のハンドルを回す。 | I35: 初代の職人 | J35: Ingredients | K35: Sepia-toned close-up: a young craftsman's hands turn the handle of an old machine in a 1940s workshop. Japanese hand-drawn anime film style, soft painterly backgrounds, warm natural light, muted colors, gentle film grain, cinematic 16:9. No on-screen text, no logos, no sparks. | L35: 年号カウンター 1948 | N35: 未生成
A36: 32 | B36: ='構成・絵コンテ'!B15 | C36: 今の手 | D36: =IF(B36=B35,D35+E35,'構成・絵コンテ'!C15) | E36: ='構成・絵コンテ'!E15/COUNTIF($B$5:$B$45,B36) | F36: =IF(E36>8,8,IF(E36>6,8,IF(E36>4,6,4))) | G36: 設備力 人間力 | H36: 同じ構図で、現在のオペレーターが最新機の操作盤を操作する。 | I36: 若手のオペレーター | J36: Frames to video（前カットと同じ構図で） | K36: Same composition in full color, present day: a young operator's hands operate the control panel of a modern machine. Japanese hand-drawn anime film style, soft painterly backgrounds, warm natural light, muted colors, gentle film grain, cinematic 16:9. No on-screen text, no logos, no sparks. | L36: 年号カウンター 2026 | N36: 未生成
A37: 33 | B37: ='構成・絵コンテ'!B15 | C37: 図面が重なる | D37: =IF(B37=B36,D36+E36,'構成・絵コンテ'!C15) | E37: ='構成・絵コンテ'!E15/COUNTIF($B$5:$B$45,B37) | F37: =IF(E37>8,8,IF(E37>6,8,IF(E37>4,6,4))) | G37: 四つの力を ひとつにして | H37: 鉛筆の図面が CAD の画面に重なり、一つになる。 | I37: ベテラン職人・若手の設計者 | J37: Frames to video | K37: A pencil-drawn blueprint slowly dissolves into the same design on a CAD screen, two hands—old and young—resting side by side. Japanese hand-drawn anime film style, soft painterly backgrounds, warm natural light, muted colors, gentle film grain, cinematic 16:9. No on-screen text, no logos, no sparks. | N37: 未生成
A38: 34 | B38: ='構成・絵コンテ'!B15 | C38: 大物を吊る | D38: =IF(B38=B37,D37+E37,'構成・絵コンテ'!C15) | E38: ='構成・絵コンテ'!E15/COUNTIF($B$5:$B$45,B38) | F38: =IF(E38>8,8,IF(E38>6,8,IF(E38>4,6,4))) | G38: 新しい時代を 切り拓け | H38: 大きな加工品がクレーンでゆっくり吊り上げられる。 | I38: ― | J38: Ingredients（現在の工場） | K38: A massive machined steel part is slowly lifted by an overhead crane, workers guiding it, camera tilting up with it. Japanese hand-drawn anime film style, soft painterly backgrounds, warm natural light, muted colors, gentle film grain, cinematic 16:9. No on-screen text, no logos, no sparks. | N38: 未生成
A39: 35 | B39: ='構成・絵コンテ'!B15 | C39: 全員集合 | D39: =IF(B39=B38,D38+E38,'構成・絵コンテ'!C15) | E39: ='構成・絵コンテ'!E15/COUNTIF($B$5:$B$45,B39) | F39: =IF(E39>8,8,IF(E39>6,8,IF(E39>4,6,4))) | G39: 1948年から／受け継いだ ものづくり | H39: 工場の前に全社員が集まり、カメラが大きく引いていく。 | I39: 全員 | J39: Ingredients | K39: All employees gathered in front of the factory, smiling; the camera pulls back and rises to reveal the whole group. Japanese hand-drawn anime film style, soft painterly backgrounds, warm natural light, muted colors, gentle film grain, cinematic 16:9. No on-screen text, no logos, no sparks. | N39: 未生成
A40: 36 | B40: ='構成・絵コンテ'!B15 | C40: 100年企業へ | D40: =IF(B40=B39,D39+E39,'構成・絵コンテ'!C15) | E40: ='構成・絵コンテ'!E15/COUNTIF($B$5:$B$45,B40) | F40: =IF(E40>8,8,IF(E40>6,8,IF(E40>4,6,4))) | G40: 100年企業へ／その先へ | H40: ベテランと若手が並び、完成品を見上げる。 | I40: ベテラン職人・若手の設計者 | J40: Ingredients | K40: The elderly craftsman and the young designer stand side by side looking up at a finished machine, light on their faces. Japanese hand-drawn anime film style, soft painterly backgrounds, warm natural light, muted colors, gentle film grain, cinematic 16:9. No on-screen text, no logos, no sparks. | L40: 年号カウンター 2048 | N40: 未生成
A41: 37 | B41: ='構成・絵コンテ'!B15 | C41: 朝日の工場 | D41: =IF(B41=B40,D40+E40,'構成・絵コンテ'!C15) | E41: ='構成・絵コンテ'!E15/COUNTIF($B$5:$B$45,B41) | F41: =IF(E41>8,8,IF(E41>6,8,IF(E41>4,6,4))) | G41: まだ見ぬ未来を／この手で創る | H41: 朝日の中の工場を、上昇しながら映す。 | I41: ― | J41: Ingredients（現在の工場） | K41: Rising aerial shot of the factory at sunrise, long shadows, birds crossing the sky. Japanese hand-drawn anime film style, soft painterly backgrounds, warm natural light, muted colors, gentle film grain, cinematic 16:9. No on-screen text, no logos, no sparks. | N41: 未生成
...

Sheet 構成・絵コンテ
A1: 構成・絵コンテ
A2: 青字の開始・終了時刻を直すと、長さ・小節数・盛り上がり・歌詞の表示時刻が自動で変わります。時刻は曲の自動解析による推定値です。
A3: テンポ（BPM） | B3: =概要!B6
A4: No | B4: パート | C4: 開始（秒） | D4: 終了（秒） | E4: 長さ（秒） | F4: 小節数 | G4: 盛り上がり（0〜1） | H4: 歌詞（冒頭） | I4: 映像の内容 | J4: 組み合わせるスタイル | K4: 音との同期 | L4: 使う素材 | M4: 制作ツール
A5: 1 | B5: イントロ | C5: 0 | D5: =C6 | E5: =D5-C5 | F5: =ROUND(E5/(60/$B$3*4),0) | G5: =IFERROR(AVERAGEIFS('曲の解析'!$B$5:$B$200,'曲の解析'!$A$5:$A$200,">="&C5,'曲の解析'!$A$5:$A$200,"<"&D5),0) | H5: （歌なし） | I5: 暗闇に鉄のブロック。エンドミルが静かに表面をなぞり、削られた面に金属の光沢が走る。工具の軌跡が光の線になって「1948」を描く。 | J5: ・シェーダー（金属の質感） ・光沢の走り（シェーダー） ・線を描く（SVG） | K5: 拍ごとに軌跡の線が1本ずつ増える。最後の拍で「1948」が完成 | L5: （素材不要・CGで制作） | M5: Remotion + Three.js
A6: 2 | B6: Aメロ1 | C6: 9.1 | D6: =C7 | E6: =D6-C6 | F6: =ROUND(E6/(60/$B$3*4),0) | G6: =IFERROR(AVERAGEIFS('曲の解析'!$B$5:$B$200,'曲の解析'!$A$5:$A$200,">="&C6,'曲の解析'!$A$5:$A$200,"<"&D6),0) | H6: 1948年 ここから始まった … | I6: 年号が 1948 → 現在 へカウントアップ。創業期〜現在の工場写真をゆっくりズーム。セピアから徐々にカラーへ。歌詞はタイピングで1行ずつ。 | J6: ・カウントアップ ・Ken Burns（ゆっくりズーム） ・タイピング ・色補正 | K6: 1小節ごとに写真を切り替え。「情熱」で色が完全にカラーに | L6: 会社沿革の写真、工場外観、創業期の写真（あれば） | M6: Remotion + FFmpeg
A7: 3 | B7: Aメロ2 | C7: 31.4 | D7: =C8 | E7: =D7-C7 | F7: =ROUND(E7/(60/$B$3*4),0) | G7: =IFERROR(AVERAGEIFS('曲の解析'!$B$5:$B$200,'曲の解析'!$A$5:$A$200,">="&C7,'曲の解析'!$A$5:$A$200,"<"&D7),0) | H7: 鉄を削り 形を生み出す … | I7: 門型5面加工機と大物ワーク。工具の軌跡（ツールパス）が線で描かれる。「一ミリ 一ミクロン」で目盛りが 1mm→1μm まで拡大。最大ワーク 5200×2600mm をカウンター表示。 | J7: ・線を描く（SVG） ・3D モデル ・カウントアップ ・スライド・拡大縮小 ・Ken Burns（ゆっくりズーム） | K7: 「一ミリ」「一ミクロン」の2拍でズームが2段階で入る | L7: 門型5面加工機の写真、大物加工中の写真、加工部品の写真 | M7: Remotion + Three.js
A8: 4 | B8: Bメロ1 | C8: 53.8 | D8: =C9 | E8: =D8-C8 | F8: =ROUND(E8/(60/$B$3*4),0) | G8: =IFERROR(AVERAGEIFS('曲の解析'!$B$5:$B$200,'曲の解析'!$A$5:$A$200,">="&C8,'曲の解析'!$A$5:$A$200,"<"&D8),0) | H8: 守るべき技術は 守り抜く … | I8: 「守る／変える」を表と裏の3Dカードで対比（表：受け継ぐ技術、裏：新しい設備）。「昨日を超えて」「今日を超えて」で画面が右へ押し出され、光の流れが加速していく。 | J8: ・3D カード反転 ・ページ遷移（スライド） ・フローフィールド | K8: サビ前の4小節で流れの速度と明るさを上げていく | L8: 昔の機械と最新設備の写真（対比用） | M8: Remotion
A9: 5 | B9: サビ1 | C9: 69 | D9: =C10 | E9: =D9-C9 | F9: =ROUND(E9/(60/$B$3*4),0) | G9: =IFERROR(AVERAGEIFS('曲の解析'!$B$5:$B$200,'曲の解析'!$A$5:$A$200,">="&C9,'曲の解析'!$A$5:$A$200,"<"&D9),0) | H9: 技術力 設計力 … | I9: 「技術力・設計力・設備力・人間力」を1拍1語で画面いっぱいに。4分割画面にそれぞれの写真。「切り拓け」で画面が切削されたように割れ、ロゴが線で描かれて3D化。 | J9: ・1文字ずつ出現 ・拍ごとのカット ・3D モデル ・光沢の走り（シェーダー） ・線を描く（SVG） | K9: 4つの力＝4拍。「原マシナリー」でロゴ確定＋光沢がロゴを横切る | L9: ロゴ（SVG推奨）、設計・設備・人の写真 | M9: Remotion + Three.js
A10: 6 | B10: 間奏 | C10: 98.1 | D10: =C11 | E10: =D10-C10 | F10: =ROUND(E10/(60/$B$3*4),0) | G10: =IFERROR(AVERAGEIFS('曲の解析'!$B$5:$B$200,'曲の解析'!$A$5:$A$200,">="&C10,'曲の解析'!$A$5:$A$200,"<"&D10),0) | H10: （歌なし） | I10: 音の波形が鉄板に刻まれるライン表現。グリッチで次のパートへ転換。 | J10: ・波のライン ・グリッチ | K10: 波形は音量に連動。最後の1拍でグリッチ | L10: （素材不要） | M10: Remotion
A11: 7 | B11: Aメロ3 | C11: 104.9 | D11: =C12 | E11: =D11-C11 | F11: =ROUND(E11/(60/$B$3*4),0) | G11: =IFERROR(AVERAGEIFS('曲の解析'!$B$5:$B$200,'曲の解析'!$A$5:$A$200,">="&C11,'曲の解析'!$A$5:$A$200,"<"&D11),0) | H11: 難しい素材も 不可能じゃない … | I11: シリコン・サファイア・ガラス・石英を、それぞれの結晶や透明感をシェーダーで表現し、名前を拍で表示。「削る 磨く 組み上げる」は3拍で3カット。専用加工機の写真。 | J11: ・シェーダー（素材の質感） ・1文字ずつ出現 ・拍ごとのカット ・Ken Burns（ゆっくりズーム） | K11: 素材名4つ＝4拍で切り替え | L11: 専用機（シリコンインゴット・サファイア等の加工機）の写真、加工サンプル | M11: Remotion + Three.js
A12: 8 | B12: Bメロ2 | C12: 122 | D12: =C13 | E12: =D12-C12 | F12: =ROUND(E12/(60/$B$3*4),0) | G12: =IFERROR(AVERAGEIFS('曲の解析'!$B$5:$B$200,'曲の解析'!$A$5:$A$200,">="&C12,'曲の解析'!$A$5:$A$200,"<"&D12),0) | H12: 品質を追い … | I12: 品質・コスト・納期の3つをチェックマークのアイコンで提示。「積み上げていく」でブロックが物理演算で積み上がり、会社のシルエットになる。 | J12: ・Lottie アイコン ・物理シミュレーション ・スケルトン → 写真への切替 | K12: 「品質を追い／コストに挑み／納期を守る」の各頭でチェック | L12: ISO9001 認証の情報、検査風景の写真 | M12: Remotion + Lottie
A13: 9 | B13: サビ2 | C13: 137 | D13: =C14 | E13: =D13-C13 | F13: =ROUND(E13/(60/$B$3*4),0) | G13: =IFERROR(AVERAGEIFS('曲の解析'!$B$5:$B$200,'曲の解析'!$A$5:$A$200,">="&C13,'曲の解析'!$A$5:$A$200,"<"&D13),0) | H13: 技術力 設計力 … | I13: 4つの力（サビ1と色違い）。「この街から 世界へ」で岡崎の地図から地球までズームアウト。自動車・航空宇宙・工作機械の業界アイコン。 | J13: ・1文字ずつ出現 ・拍ごとのカット ・3D モデル ・Lottie アイコン ・光沢の走り（シェーダー） | K13: 「世界へ」の拍で一気にズームアウト | L13: 本社所在地（岡崎市）、取引業界 | M13: Remotion + Three.js
A14: 10 | B14: Cメロ | C14: 166.2 | D14: =C15 | E14: =D14-C14 | F14: =ROUND(E14/(60/$B$3*4),0) | G14: =IFERROR(AVERAGEIFS('曲の解析'!$B$5:$B$200,'曲の解析'!$A$5:$A$200,">="&C14,'曲の解析'!$A$5:$A$200,"<"&D14),0) | H14: 変化を恐れない … | I14: テンポを落とした温かい色調。「人がいる／技術がある／仲間がいる」で社員の写真をゆっくりスライド。光の粒が漂う。「だから できる」で一瞬の静止のあと、グリッチで最後のサビへ。 | J14: ・Ken Burns（ゆっくりズーム） ・雪・光の粒 ・タイピング ・グリッチ | K14: 「だから できる」の直後に 1拍の静止（ブレイク） | L14: 社員・現場の写真、代表メッセージの写真 | M14: Remotion + FFmpeg
A15: 11 | B15: ラストサビ | C15: 196.8 | D15: =C16 | E15: =D15-C15 | F15: =ROUND(E15/(60/$B$3*4),0) | G15: =IFERROR(AVERAGEIFS('曲の解析'!$B$5:$B$200,'曲の解析'!$A$5:$A$200,">="&C15,'曲の解析'!$A$5:$A$200,"<"&D15),0) | H15: 技術力 設計力 … | I15: 最大の盛り上がり。年号カウンターが 1948 → 2048（100年企業）。全写真を拍ごとに高速モンタージュ。3D ロゴが回転し、「切り拓け」で画面全体が切削されて光が差し込む。紙吹雪と、ロゴを走る金属の光沢。 | J15: ・カウントアップ ・拍ごとのカット ・3D モデル ・シェーダー（金属の質感） ・光沢の走り（シェーダー） ・紙吹雪 ・1文字ずつ出現 | K15: 1拍1カット。「100年企業へ」でカウンターが 2048 に到達 | L15: これまでの全写真、ロゴ | M15: Remotion + Three.js
A16: 12 | B16: アウトロ | C16: 255.1 | D16: =概要!B5 | E16: =D16-C16 | F16: =ROUND(E16/(60/$B$3*4),0) | G16: =IFERROR(AVERAGEIFS('曲の解析'!$B$5:$B$200,'曲の解析'!$A$5:$A$200,">="&C16,'曲の解析'!$A$5:$A$200,"<"&D16),0) | H16: 受け継ぐ技術 … | I16: 工具の軌跡の線が静かに消え、ロゴとスローガン「受け継ぐ技術 挑み続ける心」。最後にURLを表示してフェードアウト。 | J16: ・線を描く（SVG） ・フェード ・光沢の走り（シェーダー） | K16: 曲の最後の音でロゴが確定し、余韻でフェード | L16: ロゴ、URL（hara-mc1948.co.jp） | M16: Remotion + FFmpeg
B17: 合計 | E17: =SUM(E5:E16) | F17: =SUM(F5:F16)

Sheet 歌詞テロップ
A1: 歌詞テロップ
A2: 表示時刻は、各パートの長さを行数で等分した目安です。実際の歌い出しに合わせて「補正（秒）」列に ± の値を入れて調整してください。
A4: パート | B4: パート内の行 | C4: 歌詞 | D4: 表示開始の目安（秒） | E4: 補正（秒） | F4: 表示開始（確定） | G4: 表示時間（秒） | H4: テロップの演出
A5: Aメロ1 | B5: 1 | C5: 1948年 ここから始まった | D5: ='構成・絵コンテ'!$C$6+(B5-1)*'構成・絵コンテ'!$E$6/COUNTIF($A$5:$A$200,A5) | E5: 0 | F5: =D5+E5 | G5: =IF(A6=A5,F6-F5,'構成・絵コンテ'!$D$6-F5) | H5: タイピング
A6: Aメロ1 | B6: 2 | C6: 受け継いだ技術 積み重ねた想い | D6: ='構成・絵コンテ'!$C$6+(B6-1)*'構成・絵コンテ'!$E$6/COUNTIF($A$5:$A$200,A6) | E6: 0 | F6: =D6+E6 | G6: =IF(A7=A6,F7-F6,'構成・絵コンテ'!$D$6-F6) | H6: タイピング
A7: Aメロ1 | B7: 3 | C7: 時代が変わっても | D7: ='構成・絵コンテ'!$C$6+(B7-1)*'構成・絵コンテ'!$E$6/COUNTIF($A$5:$A$200,A7) | E7: 0 | F7: =D7+E7 | G7: =IF(A8=A7,F8-F7,'構成・絵コンテ'!$D$6-F7) | H7: フェード
A8: Aメロ1 | B8: 4 | C8: 変わらないものがある | D8: ='構成・絵コンテ'!$C$6+(B8-1)*'構成・絵コンテ'!$E$6/COUNTIF($A$5:$A$200,A8) | E8: 0 | F8: =D8+E8 | G8: =IF(A9=A8,F9-F8,'構成・絵コンテ'!$D$6-F8) | H8: フェード
A9: Aメロ1 | B9: 5 | C9: ものづくりへの 情熱 | D9: ='構成・絵コンテ'!$C$6+(B9-1)*'構成・絵コンテ'!$E$6/COUNTIF($A$5:$A$200,A9) | E9: 0 | F9: =D9+E9 | G9: =IF(A10=A9,F10-F9,'構成・絵コンテ'!$D$6-F9) | H9: 1文字ずつ出現（大きく）
A10: Aメロ2 | B10: 1 | C10: 鉄を削り 形を生み出す | D10: ='構成・絵コンテ'!$C$7+(B10-1)*'構成・絵コンテ'!$E$7/COUNTIF($A$5:$A$200,A10) | E10: 0 | F10: =D10+E10 | G10: =IF(A11=A10,F11-F10,'構成・絵コンテ'!$D$7-F10) | H10: 線を描く文字
A11: Aメロ2 | B11: 2 | C11: 大きな素材に 挑み続ける | D11: ='構成・絵コンテ'!$C$7+(B11-1)*'構成・絵コンテ'!$E$7/COUNTIF($A$5:$A$200,A11) | E11: 0 | F11: =D11+E11 | G11: =IF(A12=A11,F12-F11,'構成・絵コンテ'!$D$7-F11) | H11: スライド
A12: Aメロ2 | B12: 3 | C12: 一ミリ 一ミクロン | D12: ='構成・絵コンテ'!$C$7+(B12-1)*'構成・絵コンテ'!$E$7/COUNTIF($A$5:$A$200,A12) | E12: 0 | F12: =D12+E12 | G12: =IF(A13=A12,F13-F12,'構成・絵コンテ'!$D$7-F12) | H12: 拡大（1mm）
A13: Aメロ2 | B13: 4 | C13: その先にある精度を追い | D13: ='構成・絵コンテ'!$C$7+(B13-1)*'構成・絵コンテ'!$E$7/COUNTIF($A$5:$A$200,A13) | E13: 0 | F13: =D13+E13 | G13: =IF(A14=A13,F14-F13,'構成・絵コンテ'!$D$7-F13) | H13: 拡大（1μm）
A14: Aメロ2 | B14: 5 | C14: 見えないところまで | D14: ='構成・絵コンテ'!$C$7+(B14-1)*'構成・絵コンテ'!$E$7/COUNTIF($A$5:$A$200,A14) | E14: 0 | F14: =D14+E14 | G14: =IF(A15=A14,F15-F14,'構成・絵コンテ'!$D$7-F14) | H14: フェード
A15: Aメロ2 | B15: 6 | C15: 妥協せず 向き合う | D15: ='構成・絵コンテ'!$C$7+(B15-1)*'構成・絵コンテ'!$E$7/COUNTIF($A$5:$A$200,A15) | E15: 0 | F15: =D15+E15 | G15: =IF(A16=A15,F16-F15,'構成・絵コンテ'!$D$7-F15) | H15: フェード
A16: Aメロ2 | B16: 7 | C16: 技術は 人から人へ | D16: ='構成・絵コンテ'!$C$7+(B16-1)*'構成・絵コンテ'!$E$7/COUNTIF($A$5:$A$200,A16) | E16: 0 | F16: =D16+E16 | G16: =IF(A17=A16,F17-F16,'構成・絵コンテ'!$D$7-F16) | H16: タイピング
A17: Aメロ2 | B17: 8 | C17: 想いは 未来へ | D17: ='構成・絵コンテ'!$C$7+(B17-1)*'構成・絵コンテ'!$E$7/COUNTIF($A$5:$A$200,A17) | E17: 0 | F17: =D17+E17 | G17: =IF(A18=A17,F18-F17,'構成・絵コンテ'!$D$7-F17) | H17: フェード
A18: Bメロ1 | B18: 1 | C18: 守るべき技術は 守り抜く | D18: ='構成・絵コンテ'!$C$8+(B18-1)*'構成・絵コンテ'!$E$8/COUNTIF($A$5:$A$200,A18) | E18: 0 | F18: =D18+E18 | G18: =IF(A19=A18,F19-F18,'構成・絵コンテ'!$D$8-F18) | H18: 3Dカード表
A19: Bメロ1 | B19: 2 | C19: 変えるべきものは 変えていく | D19: ='構成・絵コンテ'!$C$8+(B19-1)*'構成・絵コンテ'!$E$8/COUNTIF($A$5:$A$200,A19) | E19: 0 | F19: =D19+E19 | G19: =IF(A20=A19,F20-F19,'構成・絵コンテ'!$D$8-F19) | H19: 3Dカード裏
A20: Bメロ1 | B20: 3 | C20: 昨日を超えて | D20: ='構成・絵コンテ'!$C$8+(B20-1)*'構成・絵コンテ'!$E$8/COUNTIF($A$5:$A$200,A20) | E20: 0 | F20: =D20+E20 | G20: =IF(A21=A20,F21-F20,'構成・絵コンテ'!$D$8-F20) | H20: 右へスライド
A21: Bメロ1 | B21: 4 | C21: 今日を超えて | D21: ='構成・絵コンテ'!$C$8+(B21-1)*'構成・絵コンテ'!$E$8/COUNTIF($A$5:$A$200,A21) | E21: 0 | F21: =D21+E21 | G21: =IF(A22=A21,F22-F21,'構成・絵コンテ'!$D$8-F21) | H21: 右へスライド
A22: Bメロ1 | B22: 5 | C22: まだ見ぬ未来へ | D22: ='構成・絵コンテ'!$C$8+(B22-1)*'構成・絵コンテ'!$E$8/COUNTIF($A$5:$A$200,A22) | E22: 0 | F22: =D22+E22 | G22: =IF(A23=A22,F23-F22,'構成・絵コンテ'!$D$8-F22) | H22: 拡大しながら光る
A23: サビ1 | B23: 1 | C23: 技術力 設計力 | D23: ='構成・絵コンテ'!$C$9+(B23-1)*'構成・絵コンテ'!$E$9/COUNTIF($A$5:$A$200,A23) | E23: 0 | F23: =D23+E23 | G23: =IF(A24=A23,F24-F23,'構成・絵コンテ'!$D$9-F23) | H23: 1語1拍で全画面
A24: サビ1 | B24: 2 | C24: 設備力 人間力 | D24: ='構成・絵コンテ'!$C$9+(B24-1)*'構成・絵コンテ'!$E$9/COUNTIF($A$5:$A$200,A24) | E24: 0 | F24: =D24+E24 | G24: =IF(A25=A24,F25-F24,'構成・絵コンテ'!$D$9-F24) | H24: 1語1拍で全画面
A25: サビ1 | B25: 3 | C25: すべての力を ひとつにして | D25: ='構成・絵コンテ'!$C$9+(B25-1)*'構成・絵コンテ'!$E$9/COUNTIF($A$5:$A$200,A25) | E25: 0 | F25: =D25+E25 | G25: =IF(A26=A25,F26-F25,'構成・絵コンテ'!$D$9-F25) | H25: 1文字ずつ出現
A26: サビ1 | B26: 4 | C26: まだない価値を 創り出せ | D26: ='構成・絵コンテ'!$C$9+(B26-1)*'構成・絵コンテ'!$E$9/COUNTIF($A$5:$A$200,A26) | E26: 0 | F26: =D26+E26 | G26: =IF(A27=A26,F27-F26,'構成・絵コンテ'!$D$9-F26) | H26: 1文字ずつ出現
A27: サビ1 | B27: 5 | C27: この手で | D27: ='構成・絵コンテ'!$C$9+(B27-1)*'構成・絵コンテ'!$E$9/COUNTIF($A$5:$A$200,A27) | E27: 0 | F27: =D27+E27 | G27: =IF(A28=A27,F28-F27,'構成・絵コンテ'!$D$9-F27) | H27: 大きく1拍
A28: サビ1 | B28: 6 | C28: この技術で | D28: ='構成・絵コンテ'!$C$9+(B28-1)*'構成・絵コンテ'!$E$9/COUNTIF($A$5:$A$200,A28) | E28: 0 | F28: =D28+E28 | G28: =IF(A29=A28,F29-F28,'構成・絵コンテ'!$D$9-F28) | H28: 大きく1拍
A29: サビ1 | B29: 7 | C29: 未来を 切り拓け | D29: ='構成・絵コンテ'!$C$9+(B29-1)*'構成・絵コンテ'!$E$9/COUNTIF($A$5:$A$200,A29) | E29: 0 | F29: =D29+E29 | G29: =IF(A30=A29,F30-F29,'構成・絵コンテ'!$D$9-F29) | H29: 画面が割れる演出
A30: サビ1 | B30: 8 | C30: 原マシナリー | D30: ='構成・絵コンテ'!$C$9+(B30-1)*'構成・絵コンテ'!$E$9/COUNTIF($A$5:$A$200,A30) | E30: 0 | F30: =D30+E30 | G30: =IF(A31=A30,F31-F30,'構成・絵コンテ'!$D$9-F30) | H30: ロゴが線で描かれる
A31: Aメロ3 | B31: 1 | C31: 難しい素材も 不可能じゃない | D31: ='構成・絵コンテ'!$C$11+(B31-1)*'構成・絵コンテ'!$E$11/COUNTIF($A$5:$A$200,A31) | E31: 0 | F31: =D31+E31 | G31: =IF(A32=A31,F32-F31,'構成・絵コンテ'!$D$11-F31) | H31: タイピング
A32: Aメロ3 | B32: 2 | C32: シリコン サファイア ガラス 石英 | D32: ='構成・絵コンテ'!$C$11+(B32-1)*'構成・絵コンテ'!$E$11/COUNTIF($A$5:$A$200,A32) | E32: 0 | F32: =D32+E32 | G32: =IF(A33=A32,F33-F32,'構成・絵コンテ'!$D$11-F32) | H32: 素材名を1拍ずつ
A33: Aメロ3 | B33: 3 | C33: 削る 磨く 組み上げる | D33: ='構成・絵コンテ'!$C$11+(B33-1)*'構成・絵コンテ'!$E$11/COUNTIF($A$5:$A$200,A33) | E33: 0 | F33: =D33+E33 | G33: =IF(A34=A33,F34-F33,'構成・絵コンテ'!$D$11-F33) | H33: 1語1拍で3カット
A34: Aメロ3 | B34: 4 | C34: 一つひとつに 技術が宿る | D34: ='構成・絵コンテ'!$C$11+(B34-1)*'構成・絵コンテ'!$E$11/COUNTIF($A$5:$A$200,A34) | E34: 0 | F34: =D34+E34 | G34: =IF(A35=A34,F35-F34,'構成・絵コンテ'!$D$11-F34) | H34: フェード
A35: Aメロ3 | B35: 5 | C35: 設計から 加工まで | D35: ='構成・絵コンテ'!$C$11+(B35-1)*'構成・絵コンテ'!$E$11/COUNTIF($A$5:$A$200,A35) | E35: 0 | F35: =D35+E35 | G35: =IF(A36=A35,F36-F35,'構成・絵コンテ'!$D$11-F35) | H35: スライド
A36: Aメロ3 | B36: 6 | C36: 一貫して 応えていく | D36: ='構成・絵コンテ'!$C$11+(B36-1)*'構成・絵コンテ'!$E$11/COUNTIF($A$5:$A$200,A36) | E36: 0 | F36: =D36+E36 | G36: =IF(A37=A36,F37-F36,'構成・絵コンテ'!$D$11-F36) | H36: スライド
A37: Aメロ3 | B37: 7 | C37: 求められるものの | D37: ='構成・絵コンテ'!$C$11+(B37-1)*'構成・絵コンテ'!$E$11/COUNTIF($A$5:$A$200,A37) | E37: 0 | F37: =D37+E37 | G37: =IF(A38=A37,F38-F37,'構成・絵コンテ'!$D$11-F37) | H37: フェード
A38: Aメロ3 | B38: 8 | C38: その先へ | D38: ='構成・絵コンテ'!$C$11+(B38-1)*'構成・絵コンテ'!$E$11/COUNTIF($A$5:$A$200,A38) | E38: 0 | F38: =D38+E38 | G38: =IF(A39=A38,F39-F38,'構成・絵コンテ'!$D$11-F38) | H38: 拡大
A39: Bメロ2 | B39: 1 | C39: 品質を追い | D39: ='構成・絵コンテ'!$C$12+(B39-1)*'構成・絵コンテ'!$E$12/COUNTIF($A$5:$A$200,A39) | E39: 0 | F39: =D39+E39 | G39: =IF(A40=A39,F40-F39,'構成・絵コンテ'!$D$12-F39) | H39: チェック（Lottie）
A40: Bメロ2 | B40: 2 | C40: コストに挑み | D40: ='構成・絵コンテ'!$C$12+(B40-1)*'構成・絵コンテ'!$E$12/COUNTIF($A$5:$A$200,A40) | E40: 0 | F40: =D40+E40 | G40: =IF(A41=A40,F41-F40,'構成・絵コンテ'!$D$12-F40) | H40: チェック（Lottie）
A41: Bメロ2 | B41: 3 | C41: 納期を守る | D41: ='構成・絵コンテ'!$C$12+(B41-1)*'構成・絵コンテ'!$E$12/COUNTIF($A$5:$A$200,A41) | E41: 0 | F41: =D41+E41 | G41: =IF(A42=A41,F42-F41,'構成・絵コンテ'!$D$12-F41) | H41: チェック（Lottie）
...

Sheet スタイル組み合わせ
A1: スタイル組み合わせ表
A2: ● がそのパートで使うスタイル。1パートでメインの動きは1つに絞り、背景・文字・転換を重ねる構成です。
A4: スタイル | B4: 分類 | C4: イントロ | D4: Aメロ1 | E4: Aメロ2 | F4: Bメロ1 | G4: サビ1 | H4: 間奏 | I4: Aメロ3 | J4: Bメロ2 | K4: サビ2 | L4: Cメロ | M4: ラストサビ | N4: アウトロ | O4: 使用回数
A5: シェーダー（金属の質感） | B5: 背景 | C5: ● | M5: ● | O5: =COUNTIF(C5:N5,"●")
A6: 光沢の走り（シェーダー） | B6: 背景 | C6: ● | G6: ● | K6: ● | M6: ● | N6: ● | O6: =COUNTIF(C6:N6,"●")
A7: フローフィールド | B7: 背景 | F7: ● | O7: =COUNTIF(C7:N7,"●")
A8: 波のライン | B8: 背景 | H8: ● | O8: =COUNTIF(C8:N8,"●")
A9: シェーダー（素材の質感） | B9: 背景 | I9: ● | O9: =COUNTIF(C9:N9,"●")
A10: 雪・光の粒 | B10: 背景 | L10: ● | O10: =COUNTIF(C10:N10,"●")
A11: 3D モデル | B11: 立体 | E11: ● | G11: ● | K11: ● | M11: ● | O11: =COUNTIF(C11:N11,"●")
A12: 3D カード反転 | B12: 立体 | F12: ● | O12: =COUNTIF(C12:N12,"●")
A13: 線を描く（SVG） | B13: 文字・図形 | C13: ● | E13: ● | G13: ● | N13: ● | O13: =COUNTIF(C13:N13,"●")
A14: タイピング | B14: 文字・図形 | D14: ● | L14: ● | O14: =COUNTIF(C14:N14,"●")
A15: スライド・拡大縮小 | B15: 文字・図形 | E15: ● | O15: =COUNTIF(C15:N15,"●")
A16: 1文字ずつ出現 | B16: 文字・図形 | G16: ● | I16: ● | K16: ● | M16: ● | O16: =COUNTIF(C16:N16,"●")
A17: Ken Burns（ゆっくりズーム） | B17: 写真 | D17: ● | E17: ● | I17: ● | L17: ● | O17: =COUNTIF(C17:N17,"●")
A18: 色補正 | B18: 写真 | D18: ● | O18: =COUNTIF(C18:N18,"●")
A19: カウントアップ | B19: 情報 | D19: ● | E19: ● | M19: ● | O19: =COUNTIF(C19:N19,"●")
A20: Lottie アイコン | B20: 情報 | J20: ● | K20: ● | O20: =COUNTIF(C20:N20,"●")
A21: 物理シミュレーション | B21: 情報 | J21: ● | O21: =COUNTIF(C21:N21,"●")
A22: スケルトン → 写真への切替 | B22: 情報 | J22: ● | O22: =COUNTIF(C22:N22,"●")
A23: ページ遷移（スライド） | B23: 転換 | F23: ● | O23: =COUNTIF(C23:N23,"●")
A24: 拍ごとのカット | B24: 転換 | G24: ● | I24: ● | K24: ● | M24: ● | O24: =COUNTIF(C24:N24,"●")
A25: グリッチ | B25: 転換 | H25: ● | L25: ● | O25: =COUNTIF(C25:N25,"●")
A26: フェード | B26: 転換 | N26: ● | O26: =COUNTIF(C26:N26,"●")
A27: 紙吹雪 | B27: 演出 | M27: ● | O27: =COUNTIF(C27:N27,"●")
A28: パートごとのスタイル数 | C28: =COUNTIF(C5:C27,"●") | D28: =COUNTIF(D5:D27,"●") | E28: =COUNTIF(E5:E27,"●") | F28: =COUNTIF(F5:F27,"●") | G28: =COUNTIF(G5:G27,"●") | H28: =COUNTIF(H5:H27,"●") | I28: =COUNTIF(I5:I27,"●") | J28: =COUNTIF(J5:J27,"●") | ... N28: =COUNTIF(N5:N27,"●") | O28: =SUM(O5:O27)

Sheet 素材リスト
A1: 素材リスト
A2: ホームページの画像は使用OKとのことです。ただし、この作業環境からはサイトに接続できず、まだ取得していません。状況列（黄色）を更新してください。
A4: 素材 | B4: 使うパート | C4: 入手先（候補） | D4: 形式・条件 | E4: 状況
A5: 会社ロゴ | B5: サビ1・サビ2・ラストサビ・アウトロ | C5: https://hara-mc1948.co.jp/ （ヘッダー） | D5: SVG が理想。なければ高解像度 PNG（透過） | E5: 未取得
A6: 工場の外観写真 | B6: Aメロ1 | C6: https://hara-mc1948.co.jp/company/outline | D6: 横 1920px 以上 | E6: 未取得
A7: 創業期・昔の写真 | B7: Aメロ1・Bメロ1 | C7: 社内アーカイブ（HP になければ提供依頼） | D7: スキャン可。セピア加工はこちらで実施 | E7: 未取得
A8: 門型5面加工機の写真 | B8: Aメロ2・ラストサビ | C8: https://hara-mc1948.co.jp/large | D8: 大物ワークと一緒に写っているもの | E8: 未取得
A9: 大物加工中・加工部品の写真 | B9: Aメロ2・サビ1 | C9: https://hara-mc1948.co.jp/large | D9: 切削の瞬間や仕上げ面のアップがあると最適 | E9: 未取得
A10: 専用機（シリコン・サファイア等の加工機）の写真 | B10: Aメロ3 | C10: https://hara-mc1948.co.jp/specialized | D10: 機械全体と加工部のアップ | E10: 未取得
A11: 加工サンプル（素材別） | B11: Aメロ3 | C11: https://hara-mc1948.co.jp/specialized | D11: シリコン／サファイア／ガラス／石英 | E11: 未取得
A12: 検査・品質管理の写真 | B12: Bメロ2 | C12: 社内撮影（HP になければ） | D12: ISO9001 の取り組みが分かるもの | E12: 未取得
A13: 社員・現場の写真 | B13: サビ1・Cメロ・ラストサビ | C13: https://hara-mc1948.co.jp/company/message ほか | D13: 顔が写る場合は本人の掲載同意を確認 | E13: 未取得
A14: 代表の写真・企業理念 | B14: Cメロ | C14: https://hara-mc1948.co.jp/company/message | D14: 理念の文言はテロップにも使用可 | E14: 未取得
A15: 会社の曲（音源） | B15: 全体 | C15: 受領済み（4分36秒） | D15: 最終書き出しは WAV があればより高音質 | E15: 受領済み
A16: 歌詞 | B16: 全体 | C16: 受領済み | E16: 受領済み
A17: 取得済みの数 | E17: =COUNTIF(E5:E16,"受領済み")+COUNTIF(E5:E16,"取得済み")
A18: 全素材数 | E18: =COUNTA(A5:A16)

Sheet 書き出し仕様
A1: 書き出し仕様
A2: フル版から用途別の短縮版を作ります。長さは「構成・絵コンテ」の時刻から自動計算されます。
A4: バージョン | B4: 使う範囲 | C4: 長さ（秒） | D4: 画面比率 | E4: 解像度 | F4: 用途
A5: フル版 | B5: イントロ〜アウトロ | C5: ='構成・絵コンテ'!D16-'構成・絵コンテ'!C5 | D5: 16:9 | E5: 1920×1080 | F5: YouTube・会社ホームページ・展示会
A6: 60秒版 | B6: サビ1＋ラストサビの後半 | C6: =('構成・絵コンテ'!D9-'構成・絵コンテ'!C9)+30 | D6: 9:16 | E6: 1080×1920 | F6: Instagram リール・TikTok・YouTube ショート
A7: 30秒版 | B7: サビ1 | C7: ='構成・絵コンテ'!E9 | D7: 16:9 / 1:1 | E7: 1920×1080 | F7: Web 広告・SNS 投稿
A8: 15秒版 | B8: ラストサビの「100年企業へ」〜ロゴ | C8: 15 | D8: 9:16 | E8: 1080×1920 | F8: ティザー・広告
A9: 採用向け版 | B9: Cメロ＋ラストサビ | C9: ='構成・絵コンテ'!E14+'構成・絵コンテ'!E15 | D9: 16:9 | E9: 1920×1080 | F9: 採用ページ・会社説明会

Sheet 会社情報
A1: 会社情報（映像に使う事実）
A2: ホームページを直接読めなかったため、Web 検索結果から取得しました。映像に入れる前に正しいか確認してください。
A4: 項目 | B4: 内容 | C4: 映像での使い方 | D4: 出典
A5: 会社名 | B5: 株式会社原マシナリー | C5: ロゴ・テロップ | D5: https://hara-mc1948.co.jp/company/outline（検索結果）
A6: 創業 | B6: 1948年（昭和23年）3月 | C6: 年号カウンター 1948 → 2048 | D6: https://hara-mc1948.co.jp/company/outline（検索結果）
A7: 所在地 | B7: 愛知県岡崎市滝町字追ノ狭間6-3 | C7: 「この街から 世界へ」の地図 | D7: https://hara-mc1948.co.jp/company/outline（検索結果）
A8: 代表取締役 | B8: 原 大輔 | C8: Cメロ（代表メッセージ） | D8: https://hara-mc1948.co.jp/company/outline（検索結果）
A9: 事業1 | B9: 専用機設計製作（シリコンインゴット・サファイア・ガラス・石英・セラミック等の加工機） | C9: Aメロ3 の素材表現 | D9: https://hara-mc1948.co.jp/specialized（検索結果）
A10: 事業2 | B10: 大物精密機械加工（自動車・航空宇宙・工作機械関連部品） | C10: Aメロ2・サビ2 の業界アイコン | D10: https://hara-mc1948.co.jp/large（検索結果）
A11: 事業3 | B11: 環境関連事業（太陽光発電） | C11: （必要ならラストサビのモンタージュに） | D11: 検索結果
A12: 主要設備 | B12: 門型5面加工機（最大ワークサイズ 5200×2600mm） | C12: Aメロ2 のサイズカウンター | D12: https://hara-mc1948.co.jp/large（検索結果）
A13: 認証 | B13: ISO9001（2021年3月取得） | C13: Bメロ2 の品質パート | D13: 検索結果
A14: ルーツ | B14: 石材機械製造を足がかりに専用機へ展開 | C14: Aメロ1 の歴史パート | D14: https://hara-mc1948.co.jp/specialized（検索結果）

Sheet 曲の解析
A1: 曲の解析データ
A2: 出典：添付音源を librosa で解析（長さ 275.8 秒・テンポ 143.6 BPM・検出した拍 644 個）。音量は曲全体の最大を1とした相対値。
A4: 時刻（秒） | B4: 音量（相対） | D4: 検出した拍（秒）
A5: 0 | B5: 0.353 | D5: 0.557
A6: 2 | B6: 0.597 | D6: 0.998
A7: 4 | B7: 0.567 | D7: 1.44
A8: 6 | B8: 0.537 | D8: 1.881
A9: 8 | B9: 0.617 | D9: 2.299
A10: 10 | B10: 0.569 | D10: 2.717
A11: 12 | B11: 0.613 | D11: 3.135
A12: 14 | B12: 0.683 | D12: 3.576
A13: 16 | B13: 0.665 | D13: 4.017
A14: 18 | B14: 0.689 | D14: 4.458
A15: 20 | B15: 0.661 | D15: 4.876
A16: 22 | B16: 0.664 | D16: 5.294
... A142: 274 | B142: 0.465 | D142: 58.909
D143: 59.327
D144: 59.745
D145: 60.163
D146: 60.604
D147: 61.022
D148: 61.44
D149: 61.881
D150: 62.299
D151: 62.74
D152: 63.158
D153: 63.576
D154: 63.994
... D648: 274.344
