Workbook

Sheet 年間スケジュール
A1: 年間スケジュール（全案件まとめ）
B2: 予定 | C2: 基準日(開始)→ | D2: 46023 | E2: ←変更で日付が動きます | G2: 実績
A3: No | B3: 案件名 | C3: 担当 | D3: 開始 | E3: 終了予定 | F3: 完了 | G3: 区分 | H3: =TEXT(H4,"yyyy/m") -> 2026/1 | I3: =IF(DAY(I4)=1,TEXT(I4,"m月"),"") | J3: =IF(DAY(J4)=1,TEXT(J4,"m月"),"") | K3: =IF(DAY(K4)=1,TEXT(K4,"m月"),"") | L3: =IF(DAY(L4)=1,TEXT(L4,"m月"),"") | M3: =IF(DAY(M4)=1,TEXT(M4,"m月"),"") | N3: =IF(DAY(N4)=1,TEXT(N4,"m月"),"") | O3: =IF(DAY(O4)=1,TEXT(O4,"m月"),"") | P3: =IF(DAY(P4)=1,TEXT(P4,"m月"),"") | ... NH3: =IF(DAY(NH4)=1,TEXT(NH4,"m月"),"")
H4: =$D$2 -> 46023 | I4: =H4+1 -> 46024 | J4: =I4+1 -> 46025 | K4: =J4+1 -> 46026 | L4: =K4+1 -> 46027 | M4: =L4+1 -> 46028 | N4: =M4+1 -> 46029 | O4: =N4+1 -> 46030 | P4: =O4+1 -> 46031 | ... NH4: =NG4+1 -> 46387
H5: =TEXT(H4,"aaa") -> 木 | I5: =TEXT(I4,"aaa") -> 金 | J5: =TEXT(J4,"aaa") -> 土 | K5: =TEXT(K4,"aaa") -> 日 | L5: =TEXT(L4,"aaa") -> 月 | M5: =TEXT(M4,"aaa") -> 火 | N5: =TEXT(N4,"aaa") -> 水 | O5: =TEXT(O4,"aaa") -> 木 | ... NH5: =TEXT(NH4,"aaa") -> 木
A6: 1 | B6: A社 看板リニューアル | C6: 原マシナリ | D6: =MIN('A社_看板リニューアル'!D6:D45) -> 46128 | E6: =MAX('A社_看板リニューアル'!E6:E45) -> 46266 | F6: =IF(COUNT('A社_看板リニューアル'!F6:F45)=0,"",MAX('A社_看板リニューアル'!F6:F45)) -> 46150 | G6: 予定
G7: 実績
A8: 2 | B8: B社 QR検品ライン | C8: 佐藤 | D8: =MIN('B社_QR検品ライン'!D6:D45) -> 46152 | E8: =MAX('B社_QR検品ライン'!E6:E45) -> 46280 | F8: =IF(COUNT('B社_QR検品ライン'!F6:F45)=0,"",MAX('B社_QR検品ライン'!F6:F45)) -> 46188 | G8: 予定
G9: 実績
A10: 3 | B10: C社 設備更新 | C10: 田中 | D10: =MIN('C社_設備更新'!D6:D45) -> 46082 | E10: =MAX('C社_設備更新'!E6:E45) -> 46213 | F10: =IF(COUNT('C社_設備更新'!F6:F45)=0,"",MAX('C社_設備更新'!F6:F45)) -> 46215 | G10: 予定
G11: 実績

Sheet A社_看板リニューアル
A1: スケジュール（A社_看板リニューアル）
B2: 予定 | C2: 基準日(開始)→ | D2: 46113 | E2: ←変更で日付が動きます | G2: 実績
A3: No | B3: タスク | C3: 担当 | D3: 開始日 | E3: 締切日 | F3: 完了日 | G3: 区分 | H3: =TEXT(H4,"yyyy/m") -> 2026/4 | I3: =IF(DAY(I4)=1,TEXT(I4,"m月"),"") | J3: =IF(DAY(J4)=1,TEXT(J4,"m月"),"") | K3: =IF(DAY(K4)=1,TEXT(K4,"m月"),"") | L3: =IF(DAY(L4)=1,TEXT(L4,"m月"),"") | M3: =IF(DAY(M4)=1,TEXT(M4,"m月"),"") | N3: =IF(DAY(N4)=1,TEXT(N4,"m月"),"") | O3: =IF(DAY(O4)=1,TEXT(O4,"m月"),"") | P3: =IF(DAY(P4)=1,TEXT(P4,"m月"),"") | ... NH3: =IF(DAY(NH4)=1,TEXT(NH4,"m月"),"")
H4: =$D$2 -> 46113 | I4: =H4+1 -> 46114 | J4: =I4+1 -> 46115 | K4: =J4+1 -> 46116 | L4: =K4+1 -> 46117 | M4: =L4+1 -> 46118 | N4: =M4+1 -> 46119 | O4: =N4+1 -> 46120 | P4: =O4+1 -> 46121 | ... NH4: =NG4+1 -> 46477
H5: =TEXT(H4,"aaa") -> 水 | I5: =TEXT(I4,"aaa") -> 木 | J5: =TEXT(J4,"aaa") -> 金 | K5: =TEXT(K4,"aaa") -> 土 | L5: =TEXT(L4,"aaa") -> 日 | M5: =TEXT(M4,"aaa") -> 月 | N5: =TEXT(N4,"aaa") -> 火 | O5: =TEXT(O4,"aaa") -> 水 | ... NH5: =TEXT(NH4,"aaa") -> 水
A6: 1 | B6: 見積取得 | C6: 原副社長 | D6: 46128 | E6: 46134 | F6: 46139 | G6: 予定
G7: 実績
A8: 2 | B8: 予算書作成 | C8: 今井 | D8: 46134 | E8: 46141 | F8: 46150 | G8: 予定
G9: 実績
A10: 3 | B10: 発注(納期2か月) | C10: 井上 | D10: 46157 | E10: 46172 | G10: 予定
G11: 実績
A12: 4 | B12: 制作(2か月) | C12: 原副社長 | D12: 46174 | E12: 46233 | G12: 予定
G13: 実績
A14: 5 | B14: 工事 | D14: 46235 | E14: 46265 | G14: 予定
G15: 実績
A16: 6 | B16: 運用開始 | D16: 46266 | E16: 46266 | G16: 予定
G17: 実績
A18: 7 | G18: 予定
G19: 実績
A20: 8 | G20: 予定
G21: 実績
A22: 9 | G22: 予定
G23: 実績
A24: 10 | G24: 予定
G25: 実績
A26: 11 | G26: 予定
G27: 実績
A28: 12 | G28: 予定
G29: 実績
A30: 13 | G30: 予定
G31: 実績
A32: 14 | G32: 予定
G33: 実績
A34: 15 | G34: 予定
G35: 実績
A36: 16 | G36: 予定
G37: 実績
A38: 17 | G38: 予定
G39: 実績
A40: 18 | G40: 予定
...

Sheet B社_QR検品ライン
A1: スケジュール（B社_QR検品ライン）
B2: 予定 | C2: 基準日(開始)→ | D2: 46143 | E2: ←変更で日付が動きます | G2: 実績
A3: No | B3: タスク | C3: 担当 | D3: 開始日 | E3: 締切日 | F3: 完了日 | G3: 区分 | H3: =TEXT(H4,"yyyy/m") -> 2026/5 | I3: =IF(DAY(I4)=1,TEXT(I4,"m月"),"") | J3: =IF(DAY(J4)=1,TEXT(J4,"m月"),"") | K3: =IF(DAY(K4)=1,TEXT(K4,"m月"),"") | L3: =IF(DAY(L4)=1,TEXT(L4,"m月"),"") | M3: =IF(DAY(M4)=1,TEXT(M4,"m月"),"") | N3: =IF(DAY(N4)=1,TEXT(N4,"m月"),"") | O3: =IF(DAY(O4)=1,TEXT(O4,"m月"),"") | P3: =IF(DAY(P4)=1,TEXT(P4,"m月"),"") | ... NH3: =IF(DAY(NH4)=1,TEXT(NH4,"m月"),"")
H4: =$D$2 -> 46143 | I4: =H4+1 -> 46144 | J4: =I4+1 -> 46145 | K4: =J4+1 -> 46146 | L4: =K4+1 -> 46147 | M4: =L4+1 -> 46148 | N4: =M4+1 -> 46149 | O4: =N4+1 -> 46150 | P4: =O4+1 -> 46151 | ... NH4: =NG4+1 -> 46507
H5: =TEXT(H4,"aaa") -> 金 | I5: =TEXT(I4,"aaa") -> 土 | J5: =TEXT(J4,"aaa") -> 日 | K5: =TEXT(K4,"aaa") -> 月 | L5: =TEXT(L4,"aaa") -> 火 | M5: =TEXT(M4,"aaa") -> 水 | N5: =TEXT(N4,"aaa") -> 木 | O5: =TEXT(O4,"aaa") -> 金 | ... NH5: =TEXT(NH4,"aaa") -> 金
A6: 1 | B6: 要件定義 | C6: 佐藤 | D6: 46152 | E6: 46162 | F6: 46164 | G6: 予定
G7: 実績
A8: 2 | B8: 設計 | C8: 鈴木 | D8: 46163 | E8: 46183 | F8: 46188 | G8: 予定
G9: 実績
A10: 3 | B10: 製作 | C10: 工場 | D10: 46189 | E10: 46254 | G10: 予定
G11: 実績
A12: 4 | B12: 導入 | C12: 佐藤 | D12: 46255 | E12: 46280 | G12: 予定
G13: 実績
A14: 5 | G14: 予定
G15: 実績
A16: 6 | G16: 予定
G17: 実績
A18: 7 | G18: 予定
G19: 実績
A20: 8 | G20: 予定
G21: 実績
A22: 9 | G22: 予定
G23: 実績
A24: 10 | G24: 予定
G25: 実績
A26: 11 | G26: 予定
G27: 実績
A28: 12 | G28: 予定
G29: 実績
A30: 13 | G30: 予定
G31: 実績
A32: 14 | G32: 予定
G33: 実績
A34: 15 | G34: 予定
G35: 実績
A36: 16 | G36: 予定
G37: 実績
A38: 17 | G38: 予定
G39: 実績
A40: 18 | G40: 予定
...

Sheet C社_設備更新
A1: スケジュール（C社_設備更新）
B2: 予定 | C2: 基準日(開始)→ | D2: 46082 | E2: ←変更で日付が動きます | G2: 実績
A3: No | B3: タスク | C3: 担当 | D3: 開始日 | E3: 締切日 | F3: 完了日 | G3: 区分 | H3: =TEXT(H4,"yyyy/m") -> 2026/3 | I3: =IF(DAY(I4)=1,TEXT(I4,"m月"),"") | J3: =IF(DAY(J4)=1,TEXT(J4,"m月"),"") | K3: =IF(DAY(K4)=1,TEXT(K4,"m月"),"") | L3: =IF(DAY(L4)=1,TEXT(L4,"m月"),"") | M3: =IF(DAY(M4)=1,TEXT(M4,"m月"),"") | N3: =IF(DAY(N4)=1,TEXT(N4,"m月"),"") | O3: =IF(DAY(O4)=1,TEXT(O4,"m月"),"") | P3: =IF(DAY(P4)=1,TEXT(P4,"m月"),"") | ... NH3: =IF(DAY(NH4)=1,TEXT(NH4,"m月"),"")
H4: =$D$2 -> 46082 | I4: =H4+1 -> 46083 | J4: =I4+1 -> 46084 | K4: =J4+1 -> 46085 | L4: =K4+1 -> 46086 | M4: =L4+1 -> 46087 | N4: =M4+1 -> 46088 | O4: =N4+1 -> 46089 | P4: =O4+1 -> 46090 | ... NH4: =NG4+1 -> 46446
H5: =TEXT(H4,"aaa") -> 日 | I5: =TEXT(I4,"aaa") -> 月 | J5: =TEXT(J4,"aaa") -> 火 | K5: =TEXT(K4,"aaa") -> 水 | L5: =TEXT(L4,"aaa") -> 木 | M5: =TEXT(M4,"aaa") -> 金 | N5: =TEXT(N4,"aaa") -> 土 | O5: =TEXT(O4,"aaa") -> 日 | ... NH5: =TEXT(NH4,"aaa") -> 日
A6: 1 | B6: 現地調査 | C6: 田中 | D6: 46082 | E6: 46096 | F6: 46099 | G6: 予定
G7: 実績
A8: 2 | B8: 発注 | C8: 田中 | D8: 46097 | E8: 46127 | F8: 46132 | G8: 予定
G9: 実績
A10: 3 | B10: 据付工事 | C10: 業者 | D10: 46143 | E10: 46203 | F10: 46208 | G10: 予定
G11: 実績
A12: 4 | B12: 試運転 | C12: 田中 | D12: 46204 | E12: 46213 | F12: 46215 | G12: 予定
G13: 実績
A14: 5 | G14: 予定
G15: 実績
A16: 6 | G16: 予定
G17: 実績
A18: 7 | G18: 予定
G19: 実績
A20: 8 | G20: 予定
G21: 実績
A22: 9 | G22: 予定
G23: 実績
A24: 10 | G24: 予定
G25: 実績
A26: 11 | G26: 予定
G27: 実績
A28: 12 | G28: 予定
G29: 実績
A30: 13 | G30: 予定
G31: 実績
A32: 14 | G32: 予定
G33: 実績
A34: 15 | G34: 予定
G35: 実績
A36: 16 | G36: 予定
G37: 実績
A38: 17 | G38: 予定
G39: 実績
A40: 18 | G40: 予定
...
